Workbook
Name _1B.05.M.010.0010: #REF!
Name _1B.05.M.010.0010: #REF!
Name _1B.05.M.010.0010: #REF!
Name _1B.05.M.010.0050: #REF!
Name _1B.05.M.010.0050: #REF!
Name _1B.05.M.010.0050: #REF!
Name _1B.05.M.0100.0010: #REF!
Name _1B.05.M.0100.0010: #REF!
Name _1B.05.M.020.0010: #REF!
Name _1B.05.M.020.0010: #REF!
Name _1B.05.M.020.0020: #REF!
Name _1B.05.M.020.0020: #REF!
Name _1B.05.M.020.0030: #REF!
Name _1B.05.M.020.0030: #REF!
Name _1B.05.M.020.0040: #REF!
Name _1B.05.M.020.0040: #REF!
Name _1B.05.M.030.0010: #REF!
Name _1B.05.M.030.0010: #REF!
Name _1B.05.M.030.0020: #REF!
Name _1B.05.M.030.0020: #REF!
Name _1B.05.M.040.0010: #REF!
Name _1B.05.M.040.0010: #REF!
Name _1B.05.M.050.0010: #REF!
Name _1B.05.M.050.0010: #REF!
Name _1B.05.M.050.0020: #REF!
Name _1B.05.M.050.0020: #REF!
Name _1B.05.M.050.0030: #REF!
Name _1B.05.M.050.0030: #REF!
Name _1B.05.M.060.0020: #REF!
Name _1B.05.M.060.0020: #REF!
Name _1B.05.M.060.0100: #REF!
Name _1B.05.M.060.0100: #REF!
Name _1B.05.M.070.0010: #REF!
Name _1B.05.M.070.0010: #REF!
Name _1B.05.M.070.0020: #REF!
Name _1B.05.M.070.0020: #REF!
Name _1B.05.M.070.0030: #REF!
Name _1B.05.M.070.0030: #REF!
Name _1B.05.M.070.0040: #REF!
Name _1B.05.M.070.0040: #REF!
Name _1B.05.M.070.0050: #REF!
Name _1B.05.M.070.0050: #REF!
Name _1B.05.M.080.0010: #REF!
Name _1B.05.M.080.0010: #REF!
Name _1B.05.M.090.0010: #REF!
Name _1B.05.M.090.0010: #REF!
Name _1B.09.P.010.0010: #REF!
Name _1B.09.P.010.0010: #REF!
Name _1B.09.P.010.0020: #REF!
Name _1B.09.P.010.0020: #REF!
Name _1B.09.P.010.0030: #REF!
Name _1B.09.P.010.0030: #REF!
Name _1B.09.P.010.0040: #REF!
Name _1B.09.P.010.0040: #REF!
Name _1B.09.P.010.0050: #REF!
Name _1B.09.P.010.0050: #REF!
Name _1B.09.P.010.0060: #REF!
Name _1B.09.P.010.0060: #REF!
Name _1B.09.P.010.0070: #REF!
Name _1B.09.P.010.0070: #REF!

Sheet DB
A1: ='Weekly Progress Report'!$A$1 -> MODON - Weekly Progress Report - Construction Projects
B2: ='Weekly Progress Report'!$A$2 -> Contract General Information | J2: ='Weekly Progress Report'!G2 -> Key Dates | U2: ='Weekly Progress Report'!$M$2 -> Cost Summary (SR) | AD2: ='Weekly Progress Report'!$U$2 -> Performance Summary | AP2: ='Weekly Progress Report'!A61 -> Shop Drawings | AT2: ='Weekly Progress Report'!A70 -> Material Approval | AW2: ='Weekly Progress Report'!A79 -> Procurement Summary | BD2: ='Weekly Progress Report'!L61 -> Quality Reports | BT2: ='Weekly Progress Report'!L69 -> Key Submittals Approval Status | CD2: ='Weekly Progress Report'!L75 -> Invoices Summary | CR2: ='Weekly Progress Report'!L83 -> Resources at Site | CY2: ='Weekly Progress Report'!W61 -> Safety Statistics | FK2: ='Weekly Progress Report'!A88 -> Primavera P6 Schedule Status | FS2: ='Weekly Progress Report'!A97 -> Weekly Prgoress Photos
A3: ='Weekly Progress Report'!AF1 -> Data Date | B3: ='Weekly Progress Report'!A3 -> Project Name | C3: ='Weekly Progress Report'!A4 -> Project ID | D3: ='Weekly Progress Report'!A5 -> Contractor | E3: ='Weekly Progress Report'!A6 -> Consultant | F3: ='Weekly Progress Report'!D4 -> Stage | G3: ='Weekly Progress Report'!D5 -> Status | H3: ='Weekly Progress Report'!D6 -> Modon PM | I3: ='Weekly Progress Report'!AA2 -> Project Scope | J3: ='Weekly Progress Report'!G3 -> Contract Award | K3: ='Weekly Progress Report'!G4 -> Contract Sign | L3: ='Weekly Progress Report'!G5 -> Site Handover | M3: ='Weekly Progress Report'!G6 -> Original Completion | N3: ='Weekly Progress Report'!$I$3 -> Contract Award (Hijri) | O3: ='Weekly Progress Report'!$I$4 -> Contract Sign (Hijri) | P3: ='Weekly Progress Report'!$I$5 -> Site Handover (Hijri) | Q3: ='Weekly Progress Report'!$I$6 -> Original Completion (Hijri) | R3: ='Weekly Progress Report'!$K$3 -> Revised Completion | S3: ='Weekly Progress Report'!$K$4 -> Committed Completion | T3: ='Weekly Progress Report'!$K$5 -> Forecast Completion | U3: ='Weekly Progress Report'!$M$3 -> Original Contract Value | V3: ='Weekly Progress Report'!$M$4 -> Revised Contract Value | W3: ='Weekly Progress Report'!$M$5 -> Estimate At Completion Value | X3: ='Weekly Progress Report'!$M$6 -> Potential Changes | Y3: ='Weekly Progress Report'!$Q$3 -> O&M Value (if any) | Z3: ='Weekly Progress Report'!$Q$4 -> Submitted Invoices (Gross Value) | AA3: ='Weekly Progress Report'!$Q$5 -> Penalities | AB3: ='Weekly Progress Report'!$Q$6 -> FIR Value (Todate) | AC3: Original Plan Value | AD3: ='Weekly Progress Report'!$U$3 -> Plan Value | AE3: ='Weekly Progress Report'!$U$4 -> Earn Value | AF3: ='Weekly Progress Report'!$W$3 -> Phys. Plan Value | AG3: ='Weekly Progress Report'!$W$4 -> Phys. Earn Value | AH3: ='Weekly Progress Report'!$Y$3 -> Quality Score | AI3: ='Weekly Progress Report'!$Y$5 -> Safety Score | AJ3: Weekly PV (SAR) | AK3: Weekly EV (SAR) | AL3: Weekly PV % | AM3: Weekly PV % | AN3: Weekly Phys PV% | AO3: Weekly Phys PV% | AP3: Total SD Planned | AQ3: SD Remaining | AR3: SD Pending | AS3: Total SD Submittals | AT3: Planned Materials Approv | AU3: Material Pending Approval | AV3: Materila Total Submittals | AW3: ='Weekly Progress Report'!C80 -> Total Materials | AX3: ='Weekly Progress Report'!D80 -> Total Number of P.O. | AY3: ='Weekly Progress Report'!E80 -> Actual P.O. To Date | AZ3: ='Weekly Progress Report'!F80 -> Remaining P.O | BA3: ='Weekly Progress Report'!G80 -> Material on Site | BB3: ='Weekly Progress Report'!H80 -> Remaining Materials | BC3: ='Weekly Progress Report'!I80 -> Material Delivery Completion (Date) | BD3: ="NCR "&'Weekly Progress Report'!N62 -> NCR Issued | BE3: ="NCR "&'Weekly Progress Report'!O62 -> NCR Closed | BF3: ="NCR "&'Weekly Progress Report'!P62 -> NCR Pending | BG3: ="NCR "&'Weekly Progress Report'!Q62 -> NCR Avg. Closing (Days) | BH3: ="SIR "&'Weekly Progress Report'!N62 -> SIR Issued | BI3: ="SIR "&'Weekly Progress Report'!O62 -> SIR Closed | BJ3: ="SIR "&'Weekly Progress Report'!P62 -> SIR Pending | BK3: ="SIR "&'Weekly Progress Report'!Q62 -> SIR Avg. Closing (Days) | BL3: ="MIR "&'Weekly Progress Report'!N62 -> MIR Issued | BM3: ="MIR "&'Weekly Progress Report'!O62 -> MIR Closed | BN3: ="MIR "&'Weekly Progress Report'!P62 -> MIR Pending | BO3: ="MIR "&'Weekly Progress Report'!Q62 -> MIR Avg. Closing (Days) | BP3: ="FIR "&'Weekly Progress Report'!N62 -> FIR Issued | BQ3: ="FIR "&'Weekly Progress Report'!O62 -> FIR Closed | BR3: ="FIR "&'Weekly Progress Report'!P62 -> FIR Pending | BS3: ="FIR "&'Weekly Progress Report'!Q62 -> FIR Avg. Closing (Days) | BT3: ='Weekly Progress Report'!L70 -> 1 Quality Plan Approval | BU3: ='Weekly Progress Report'!L71 -> 2 Quality Plan Last Up | BV3: ='Weekly Progress Report'!L72 -> 3 Safety Plan Approval | BW3: ='Weekly Progress Report'!L73 -> 4 Safety Plan Last Up | BX3: ='Weekly Progress Report'!L74 -> 5 Construction Plan Approval | BY3: ='Weekly Progress Report'!Q70 -> 6 Baseline Approval | BZ3: ='Weekly Progress Report'!Q71 -> 7 No of Approved Version of Schedule | CA3: ='Weekly Progress Report'!Q72 -> 8 Last Approved Schedule | CB3: ='Weekly Progress Report'!Q73 -> 9 BOQ Approval Date | CC3: ='Weekly Progress Report'!Q74 -> 10 No of Approved Version of BOQ | CD3: ='Weekly Progress Report'!L76 -> Total Submitted Invoices | CE3: ='Weekly Progress Report'!L77 -> PM Approved Invoices | CF3: ='Weekly Progress Report'!L78 -> No of Paid Invoices | CG3: ='Weekly Progress Report'!L79 -> No of Pending Invoices | CH3: ='Weekly Progress Report'!L80 -> Advance Payment % | CI3: ='Weekly Progress Report'!L81 -> Retention % | CJ3: ='Weekly Progress Report'!L82 -> Deduction / Penalties % | CK3: ='Weekly Progress Report'!O76 -> Submitted Invoices (SAR) | CL3: ='Weekly Progress Report'!O77 -> PM Approved Invoices (SAR) | CM3: ='Weekly Progress Report'!O78 -> Paid Invoices (SAR) | CN3: ='Weekly Progress Report'!O79 -> Last Submitted Period | CO3: ='Weekly Progress Report'!O80 -> Advance Payment (SAR) | CP3: ='Weekly Progress Report'!O81 -> Retention (SAR) | CQ3: ='Weekly Progress Report'!O82 -> Deduction / Penalties (SAR) | CR3: Planned Head Count | CS3: Actual Head Count | CT3: Saudi Staff | CU3: Labor Planned | CV3: Labor Actual | CW3: Equipment Planned | CX3: Equipment Actual | CY3: ="This Week "&'Weekly Progress Report'!X64 -> This Week Total Hours Worked | CZ3: ="This Week "&'Weekly Progress Report'!X65 -> This Week Safe Hours Worked | DA3: ="This Week "&'Weekly Progress Report'!X66 -> This Week LTI | DB3: ="This Week "&'Weekly Progress Report'!X67 -> This Week MTC (Healed w/o Disability) | DC3: ="This Week "&'Weekly Progress Report'!X68 -> This Week MTC (Healed w/ Disability) | DD3: ="This Week "&'Weekly Progress Report'!X69 -> This Week Near Miss | DE3: ="This Week "&'Weekly Progress Report'!X70 -> This Week First Aid Cases | DF3: ="This Week "&'Weekly Progress Report'!X71 -> This Week Fatality | DG3: ="This Week "&'Weekly Progress Report'!X72 -> This Week Fire Incident Cases | DH3: ="This Week "&'Weekly Progress Report'!X73 -> This Week Vehicle Incident | DI3: ="This Week "&'Weekly Progress Report'!X74 -> This Week Property Damages | DJ3: ="This Week "&'Weekly Progress Report'!X75 -> This Week Induction Training | DK3: ="This Week "&'Weekly Progress Report'!X76 -> This Week No.of Internal Training | DL3: ="This Week "&'Weekly Progress Report'!X77 -> This Week No.of Internal Audit | DM3: ="This Week "&'Weekly Progress Report'!X78 -> This Week No. of Toolbox Talks | DN3: ="This Week "&'Weekly Progress Report'!X79 -> This Week Safety Awards/Incentives | DO3: ="This Month "&'Weekly Progress Report'!X64 -> This Month Total Hours Worked | DP3: ="This Month "&'Weekly Progress Report'!X65 -> This Month Safe Hours Worked | DQ3: ="This Month "&'Weekly Progress Report'!X66 -> This Month LTI | DR3: ="This Month "&'Weekly Progress Report'!X67 -> This Month MTC (Healed w/o Disability) | DS3: ="This Month "&'Weekly Progress Report'!X68 -> This Month MTC (Healed w/ Disability) | DT3: ="This Month "&'Weekly Progress Report'!X69 -> This Month Near Miss | DU3: ="This Month "&'Weekly Progress Report'!X70 -> This Month First Aid Cases | DV3: ="This Month "&'Weekly Progress Report'!X71 -> This Month Fatality | DW3: ="This Month "&'Weekly Progress Report'!X72 -> This Month Fire Incident Cases | DX3: ="This Month "&'Weekly Progress Report'!X73 -> This Month Vehicle Incident | DY3: ="This Month "&'Weekly Progress Report'!X74 -> This Month Property Damages | DZ3: ="This Month "&'Weekly Progress Report'!X75 -> This Month Induction Training | EA3: ="This Month "&'Weekly Progress Report'!X76 -> This Month No.of Internal Training | EB3: ="This Month "&'Weekly Progress Report'!X77 -> This Month No.of Internal Audit | EC3: ="This Month "&'Weekly Progress Report'!X78 -> This Month No. of Toolbox Talks | ED3: ="This Month "&'Weekly Progress Report'!X79 -> This Month Safety Awards/Incentives | EE3: ="YTD "&'Weekly Progress Report'!X64 -> YTD Total Hours Worked | EF3: ="YTD "&'Weekly Progress Report'!X65 -> YTD Safe Hours Worked | EG3: ="YTD "&'Weekly Progress Report'!X66 -> YTD LTI | EH3: ="YTD "&'Weekly Progress Report'!X67 -> YTD MTC (Healed w/o Disability) | EI3: ="YTD "&'Weekly Progress Report'!X68 -> YTD MTC (Healed w/ Disability) | EJ3: ="YTD "&'Weekly Progress Report'!X69 -> YTD Near Miss | EK3: ="YTD "&'Weekly Progress Report'!X70 -> YTD First Aid Cases | EL3: ="YTD "&'Weekly Progress Report'!X71 -> YTD Fatality | EM3: ="YTD "&'Weekly Progress Report'!X72 -> YTD Fire Incident Cases | EN3: ="YTD "&'Weekly Progress Report'!X73 -> YTD Vehicle Incident | EO3: ="YTD "&'Weekly Progress Report'!X74 -> YTD Property Damages | EP3: ="YTD "&'Weekly Progress Report'!X75 -> YTD Induction Training | EQ3: ="YTD "&'Weekly Progress Report'!X76 -> YTD No.of Internal Training | ER3: ="YTD "&'Weekly Progress Report'!X77 -> YTD No.of Internal Audit | ES3: ="YTD "&'Weekly Progress Report'!X78 -> YTD No. of Toolbox Talks | ET3: ="YTD "&'Weekly Progress Report'!X79 -> YTD Safety Awards/Incentives | EU3: ="Cum "&'Weekly Progress Report'!X64 -> Cum Total Hours Worked | EV3: ="Cum "&'Weekly Progress Report'!X65 -> Cum Safe Hours Worked | EW3: ="Cum "&'Weekly Progress Report'!X66 -> Cum LTI | EX3: ="Cum "&'Weekly Progress Report'!X67 -> Cum MTC (Healed w/o Disability) | EY3: ="Cum "&'Weekly Progress Report'!X68 -> Cum MTC (Healed w/ Disability) | EZ3: ="Cum "&'Weekly Progress Report'!X69 -> Cum Near Miss | FA3: ="Cum "&'Weekly Progress Report'!X70 -> Cum First Aid Cases | FB3: ="Cum "&'Weekly Progress Report'!X71 -> Cum Fatality | FC3: ="Cum "&'Weekly Progress Report'!X72 -> Cum Fire Incident Cases | FD3: ="Cum "&'Weekly Progress Report'!X73 -> Cum Vehicle Incident | FE3: ="Cum "&'Weekly Progress Report'!X74 -> Cum Property Damages | FF3: ="Cum "&'Weekly Progress Report'!X75 -> Cum Induction Training | FG3: ="Cum "&'Weekly Progress Report'!X76 -> Cum No.of Internal Training | FH3: ="Cum "&'Weekly Progress Report'!X77 -> Cum No.of Internal Audit | FI3: ="Cum "&'Weekly Progress Report'!X78 -> Cum No. of Toolbox Talks | FJ3: ="Cum "&'Weekly Progress Report'!X79 -> Cum Safety Awards/Incentives | FK3: ='Weekly Progress Report'!A91 -> Total Act. | FL3: ='Weekly Progress Report'!B91 -> Not Started | FM3: ='Weekly Progress Report'!C91 -> In Progress | FN3: ='Weekly Progress Report'!D91 -> Completed | FO3: Critical Path Act.Last Week | FP3: Critical Path Act.This Week | FQ3: Failed start Last Week | FR3: Failed start This Week | FS3: ='Weekly Progress Report'!B99 -> 0 | FT3: ='Weekly Progress Report'!D99 -> 0 | FU3: ='Weekly Progress Report'!F99 -> 0 | FV3: ='Weekly Progress Report'!H99 -> 0 | FW3: ='Weekly Progress Report'!J99 -> 0 | FX3: ='Weekly Progress Report'!L99 -> 0 | FY3: ='Weekly Progress Report'!N99 -> 0 | FZ3: ='Weekly Progress Report'!O99 -> 0 | GA3: ='Weekly Progress Report'!P99 -> 0
A4: ='Weekly Progress Report'!AG1 -> 46286 | B4: ='Weekly Progress Report'!B3 -> Factories Low-process Unit (HAFR Al Batin) | C4: ='Weekly Progress Report'!B4 -> HFR1-05-03 | D4: ='Weekly Progress Report'!B5 -> SOROH AL KHAIR CONTRACTING CO. | E4: ='Weekly Progress Report'!B6 -> EGIS | F4: ='Weekly Progress Report'!E4 -> Construction | G4: ='Weekly Progress Report'!E5 -> Active | H4: ='Weekly Progress Report'!E6 -> Eng. Mohammed Al Essa | I4: ='Weekly Progress Report'!AA3 -> The Project scope of work to construct a Factories of low process unit (Hafr Al Batin) industrial city that refer to specific tasks and activities involved in a project. This typically includes activities such as site preparation, Excavation, Foundation work, Structural construction work, Installation of utilities, Finishing works, Electrical Work, Mechanical Works and Landscaping. The scope outlines what will be done and by whom and within the planned timeframe. | J4: ='Weekly Progress Report'!H3 -> 45945 | K4: ='Weekly Progress Report'!H4 -> 45977 | L4: ='Weekly Progress Report'!H5 -> 45988 | M4: ='Weekly Progress Report'!H6 -> 46291 | N4: ='Weekly Progress Report'!$J$3 -> 45945 | O4: ='Weekly Progress Report'!$J$4 -> 45977 | P4: ='Weekly Progress Report'!$J$5 -> 45988 | Q4: ='Weekly Progress Report'!$J$6 -> 46291 | R4: ='Weekly Progress Report'!$L$3 -> 46291 | S4: ='Weekly Progress Report'!$L$4 -> 46324 | T4: ='Weekly Progress Report'!$L$5 -> 46333 | U4: ='Weekly Progress Report'!$O$3 -> 16496856 | V4: ='Weekly Progress Report'!$O$4 -> 16496856 | W4: ='Weekly Progress Report'!$O$5 -> 16496856 | X4: ='Weekly Progress Report'!$O$6 -> 0 | Y4: ='Weekly Progress Report'!$S$3 -> 0 | Z4: ='Weekly Progress Report'!$S$4 -> 10687825 | AA4: ='Weekly Progress Report'!$S$5 -> -141000 | AB4: ='Weekly Progress Report'!$S$6 -> 11743680 | AC4: ='Weekly Progress Report'!$J$31 -> 0.99545455 | AD4: ='Weekly Progress Report'!$V$3 -> 0.99545455 | AE4: ='Weekly Progress Report'!$V$4 -> 0.98173011 | AF4: ='Weekly Progress Report'!$X$3 -> 0.9971756 | AG4: ='Weekly Progress Report'!$X$4 -> 0.98016783 | AH4: ='Weekly Progress Report'!$Z$3 -> 0.79137931 | AI4: ='Weekly Progress Report'!$Z$5 -> 0.78846154 | AJ4: ='Weekly Progress Report'!$E$31 -> 311438.92 | AK4: ='Weekly Progress Report'!$F$31 -> 195657.68 | AL4: =AJ4/V4 -> 0.018878683 | AM4: =AK4/V4 -> 0.011860301 | AN4: ='Weekly Progress Report'!S31 -> 0.0095101651 | AO4: ='Weekly Progress Report'!T31 -> 0.019422841 | AP4: ='Weekly Progress Report'!C69 -> 266 | AQ4: ='Weekly Progress Report'!I69 -> 0 | AR4: ='Weekly Progress Report'!J69 -> 0 | AS4: ='Weekly Progress Report'!K69 -> 266 | AT4: ='Weekly Progress Report'!C78 -> 86 | AU4: ='Weekly Progress Report'!J78 -> 2 | AV4: ='Weekly Progress Report'!K78 -> 86 | AW4: ='Weekly Progress Report'!C87 -> 93 | AX4: ='Weekly Progress Report'!D87 -> 93 | AY4: ='Weekly Progress Report'!E87 -> 93 | AZ4: ='Weekly Progress Report'!F87 -> 0 | BA4: ='Weekly Progress Report'!G87 -> 93 | BB4: ='Weekly Progress Report'!H87 -> 0 | BC4: ='Weekly Progress Report'!I87 -> 46284 | BD4: ='Weekly Progress Report'!N65 -> 7 | BE4: ='Weekly Progress Report'!O65 -> 7 | BF4: ='Weekly Progress Report'!P65 -> 0 | BG4: ='Weekly Progress Report'!Q65 -> 0 | BH4: ='Weekly Progress Report'!N66 -> 15 | BI4: ='Weekly Progress Report'!O66 -> 15 | BJ4: ='Weekly Progress Report'!P66 -> 0 | BK4: ='Weekly Progress Report'!Q66 -> 0 | BL4: ='Weekly Progress Report'!N67 -> 81 | BM4: ='Weekly Progress Report'!O67 -> 65 | BN4: ='Weekly Progress Report'!P67 -> 16 | BO4: ='Weekly Progress Report'!Q67 -> 0 | BP4: ='Weekly Progress Report'!N68 -> 727 | BQ4: ='Weekly Progress Report'!O68 -> 716 | BR4: ='Weekly Progress Report'!P68 -> 11 | BS4: ='Weekly Progress Report'!Q68 -> 0 | BT4: ='Weekly Progress Report'!O70 -> 46106 | BU4: ='Weekly Progress Report'!O71 -> 46106 | BV4: ='Weekly Progress Report'!O72 -> 46287 | BW4: ='Weekly Progress Report'!O73 -> 0 | BX4: ='Weekly Progress Report'!O74 -> 0 | BY4: ='Weekly Progress Report'!U70 -> 46088 | BZ4: ='Weekly Progress Report'!U71 -> 2 | CA4: ='Weekly Progress Report'!U72 -> 46088 | CB4: ='Weekly Progress Report'!U73 -> 46158 | CC4: ='Weekly Progress Report'!U74 -> 0 | CD4: ='Weekly Progress Report'!N76 -> 5 | CE4: ='Weekly Progress Report'!N77 -> 0 | CF4: ='Weekly Progress Report'!N78 -> 0 | CG4: ='Weekly Progress Report'!N79 -> 0 | CH4: ='Weekly Progress Report'!N80 -> 0.1 | CI4: ='Weekly Progress Report'!N81 -> 0 | CJ4: ='Weekly Progress Report'!N82 -> 0.0085470832 | CK4: ='Weekly Progress Report'!R76 -> 10687825 | CL4: ='Weekly Progress Report'!R77 -> 0 | CM4: ='Weekly Progress Report'!R78 -> 281548.46 | CN4: ='Weekly Progress Report'!R79 -> 46254 | CO4: ='Weekly Progress Report'!R80 -> 1649685.6 | CP4: ='Weekly Progress Report'!R81 -> 0 | CQ4: ='Weekly Progress Report'!R82 -> -141000 | CR4: ='Weekly Progress Report'!L86 -> 12 | CS4: ='Weekly Progress Report'!M86 -> 10 | CT4: ='Weekly Progress Report'!O86 -> 0 | CU4: ='Weekly Progress Report'!P86 -> 34 | CV4: ='Weekly Progress Report'!Q86 -> 58 | CW4: ='Weekly Progress Report'!T96 -> 0 | CX4: ='Weekly Progress Report'!U96 -> 13 | CY4: ='Weekly Progress Report'!Z64 -> 3480 | CZ4: ='Weekly Progress Report'!Z65 -> 3480 | DA4: ='Weekly Progress Report'!Z66 -> 0 | DB4: ='Weekly Progress Report'!Z67 -> 0 | DC4: ='Weekly Progress Report'!Z68 -> 0 | DD4: ='Weekly Progress Report'!Z69 -> 0 | DE4: ='Weekly Progress Report'!Z70 -> 0 | DF4: ='Weekly Progress Report'!Z71 -> 0 | DG4: ='Weekly Progress Report'!Z72 -> 0 | DH4: ='Weekly Progress Report'!Z73 -> 0 | DI4: ='Weekly Progress Report'!Z74 -> 0 | DJ4: ='Weekly Progress Report'!Z75 -> 0 | DK4: ='Weekly Progress Report'!Z76 -> 0 | DL4: ='Weekly Progress Report'!Z77 -> 0 | DM4: ='Weekly Progress Report'!Z78 -> 0 | DN4: ='Weekly Progress Report'!Z79 -> 0 | DO4: ='Weekly Progress Report'!AB64 -> 11400 | DP4: ='Weekly Progress Report'!AB65 -> 11400 | DQ4: ='Weekly Progress Report'!AB66 -> 0 | DR4: ='Weekly Progress Report'!AB67 -> 0 | DS4: ='Weekly Progress Report'!AB68 -> 0 | DT4: ='Weekly Progress Report'!AB69 -> 0 | DU4: ='Weekly Progress Report'!AB70 -> 0 | DV4: ='Weekly Progress Report'!AB71 -> 0 | DW4: ='Weekly Progress Report'!AB72 -> 0 | DX4: ='Weekly Progress Report'!AB73 -> 0 | DY4: ='Weekly Progress Report'!AB74 -> 0 | DZ4: ='Weekly Progress Report'!AB75 -> 7 | EA4: ='Weekly Progress Report'!AB76 -> 4 | EB4: ='Weekly Progress Report'!AB77 -> 1 | EC4: ='Weekly Progress Report'!AB78 -> 18 | ED4: ='Weekly Progress Report'!AB79 -> 0 | EE4: ='Weekly Progress Report'!AC64 -> 143630 | EF4: ='Weekly Progress Report'!AC65 -> 143630 | EG4: ='Weekly Progress Report'!AC66 -> 0 | EH4: ='Weekly Progress Report'!AC67 -> 0 | EI4: ='Weekly Progress Report'!AC68 -> 0 | EJ4: ='Weekly Progress Report'!AC69 -> 0 | EK4: ='Weekly Progress Report'!AC70 -> 0 | EL4: ='Weekly Progress Report'!AC71 -> 0 | EM4: ='Weekly Progress Report'!AC72 -> 0 | EN4: ='Weekly Progress Report'!AC73 -> 0 | EO4: ='Weekly Progress Report'!AC74 -> 0 | EP4: ='Weekly Progress Report'!AC75 -> 11 | EQ4: ='Weekly Progress Report'!AC76 -> 5 | ER4: ='Weekly Progress Report'!AC77 -> 5 | ES4: ='Weekly Progress Report'!AC78 -> 23 | ET4: ='Weekly Progress Report'!AC79 -> 0 | EU4: ='Weekly Progress Report'!AD64 -> 143630 | EV4: ='Weekly Progress Report'!AD65 -> 143630 | EW4: ='Weekly Progress Report'!AD66 -> 0 | EX4: ='Weekly Progress Report'!AD67 -> 0 | EY4: ='Weekly Progress Report'!AD68 -> 0 | EZ4: ='Weekly Progress Report'!AD69 -> 0 | FA4: ='Weekly Progress Report'!AD70 -> 0 | FB4: ='Weekly Progress Report'!AD71 -> 0 | FC4: ='Weekly Progress Report'!AD72 -> 0 | FD4: ='Weekly Progress Report'!AD73 -> 0 | FE4: ='Weekly Progress Report'!AD74 -> 0 | FF4: ='Weekly Progress Report'!AD75 -> 11 | FG4: ='Weekly Progress Report'!AD76 -> 5 | FH4: ='Weekly Progress Report'!AD77 -> 5 | FI4: ='Weekly Progress Report'!AD78 -> 23 | FJ4: ='Weekly Progress Report'!AD79 -> 0 | FK4: ='Weekly Progress Report'!A92 -> 902 | FL4: ='Weekly Progress Report'!B92 -> 9 | FM4: ='Weekly Progress Report'!C92 -> 40 | FN4: ='Weekly Progress Report'!D92 -> 854 | FO4: ='Weekly Progress Report'!A96 -> 12 | FP4: ='Weekly Progress Report'!B96 -> 2 | FQ4: ='Weekly Progress Report'!H96 -> 11 | FR4: ='Weekly Progress Report'!I96 -> 10 | FS4: ='Weekly Progress Report'!B104 -> 0 | FT4: ='Weekly Progress Report'!D104 -> 0 | FU4: ='Weekly Progress Report'!F104 -> 0 | FV4: ='Weekly Progress Report'!H104 -> 0 | FW4: ='Weekly Progress Report'!J104 -> 0 | FX4: ='Weekly Progress Report'!L104 -> 0 | FY4: ='Weekly Progress Report'!N104 -> 0 | FZ4: ='Weekly Progress Report'!O104 -> 0 | GA4: ='Weekly Progress Report'!P104 -> 0

Sheet Weekly Progress Report
A1: MODON - Weekly Progress Report - Construction Projects | AF1: Data Date | AG1: ='General Information'!L1 -> 46286
A2: Contract General Information | G2: Key Dates | M2: Cost Summary (SR) | U2: Performance Summary | AA2: Project Scope
A3: Project Name | B3: ='General Information'!C3 -> Factories Low-process Unit (HAFR Al Batin) | G3: Contract Award | H3: ='General Information'!C12 -> 45945 | I3: Contract Award (Hijri) | J3: ='General Information'!C16 -> 45945 | K3: Revised Completion | L3: ='General Information'!C15 -> 46291 | M3: Original Contract Value | O3: ='Invoice Log'!E3 -> 16496856 | Q3: O&M Value (if any) | S3: ='Invoice Log'!I3 -> 0 | T3: EAC | U3: Plan Value | V3: =K31 -> 0.99545455 | W3: Phys. Plan Value | X3: =W31 -> 0.9971756 | Y3: Quality Score | Z3: =Quality!AC10 -> 0.79137931 | AA3: =+Progress!B1 -> The Project scope of work to construct a Factories of low process unit (Hafr Al Batin) industrial city that refer to specific tasks and activities involved in a project. This typically includes activities such as site preparation, Excavation, Foundation work, Structural construction work, Installation of utilities, Finishing works, Electrical Work, Mechanical Works and Landscaping. The scope outlines what will be done and by whom and within the planned timeframe.
A4: Project ID | B4: ='General Information'!C4 -> HFR1-05-03 | D4: Stage | E4: ='General Information'!C7 -> Construction | G4: Contract Sign | H4: ='General Information'!C13 -> 45977 | I4: Contract Sign (Hijri) | J4: ='General Information'!C17 -> 45977 | K4: Committed Completion | L4: ='General Information'!C21 -> 46324 | M4: Revised Contract Value | O4: ='Invoice Log'!E4 -> 16496856 | P4: EAC | Q4: Submitted Invoices (Gross Value) | S4: ='Invoice Log'!I5 -> 10687825 | U4: Earn Value | V4: =L31 -> 0.98173011 | W4: Phys. Earn Value | X4: =X31 -> 0.98016783 | Z4: =REPT("¢",IF(INT(+Z3*10)>5,5,INT(+Z3*10)))&REPT("£",IF(INT(+Z3*10)>5,0,5-INT(+Z3*10)))&CHAR(10)&REPT("¢",+IF(INT(+Z3*10)>5,-5+INT(+Z3*10),0))&REPT("£",IF(INT(+Z3*10)>5,10-INT(+Z3*10),5)) -> ¢¢¢¢¢ ¢¢£££
A5: Contractor | B5: ='General Information'!C5 -> SOROH AL KHAIR CONTRACTING CO. | D5: Status | E5: ='General Information'!C8 -> Active | G5: Site Handover | H5: ='General Information'!C14 -> 45988 | I5: Site Handover (Hijri) | J5: ='General Information'!C18 -> 45988 | K5: Forecast Completion | L5: ='General Information'!C22 -> 46333 | M5: Estimate At Completion Value | O5: ='Invoice Log'!E5 -> 16496856 | P5: =+#REF!+#REF!+O5 -> #REF! | Q5: Penalities | S5: ='Invoice Log'!I59 -> -141000 | U5: Variance | V5: =V4-V3 -> -0.013724444 | W5: Variance | X5: =Y31 -> -0.017007777 | Y5: Safety Score | Z5: ='HSE-Stat'!J23 -> 0.78846154
A6: Consultant | B6: ='General Information'!C6 -> EGIS | D6: Modon PM | E6: ='General Information'!C9 -> Eng. Mohammed Al Essa | G6: Original Completion | H6: ='General Information'!C15 -> 46291 | I6: Original Completion (Hijri) | J6: ='General Information'!C19 -> 46291 | K6: Variance | L6: ='General Information'!C23 -> -42 | M6: Potential Changes | O6: =O4-O5 -> 0 | Q6: FIR Value (Todate) | S6: ='FIR from Begining up to date '!K328 -> 11743680 | U6: FIR % | V6: =S6/O4 -> 0.71187384 | W6: Invoiced % | X6: =S4/O4 -> 0.64787044 | Z6: =REPT("¢",IF(INT(+Z5*10)>5,5,INT(+Z5*10)))&REPT("£",IF(INT(+Z5*10)>5,0,5-INT(+Z5*10)))&CHAR(10)&REPT("¢",+IF(INT(+Z5*10)>5,-5+INT(+Z5*10),0))&REPT("£",IF(INT(+Z5*10)>5,10-INT(+Z5*10),5)) -> ¢¢¢¢¢ ¢¢£££
A8: Progress Overview
A9: Earned Value Progress (SAR) | O9: Physical Progress (Effort) | AA9: Earned Value Progress (%)
A10: WBS | C10: BOQ Value (SAR) | D10: % Wt. | E10: Weekly (SAR) | G10: To Date (SAR) | O10: Budgeted | P10: % Wt. | Q10: Weekly Physical Progress | U10: To Date Physical Progress
E11: Planned | F11: Earned | G11: Original Plan | H11: Revised Planned | I11: Earned | J11: Original Plan % | K11: Revised Planned % | L11: Earned % | M11: Variance | N11: SPI | O11: (Manhours) | Q11: Planned | R11: Earned | S11: Plan % | T11: Earned % | U11: Planned | V11: Earned | W11: Plan % | X11: Earned % | Y11: Variance | Z11: SPI
A12: =Progress!A8 -> Mobilization | C12: =Progress!C8 -> 0 | D12: =IF(ISBLANK(C12),"",C12/$C$31) -> 0 | E12: =Progress!E8 -> 0 | F12: =Progress!F8 -> 0 | G12: =Progress!G8 -> 0 | H12: =Progress!H8 -> 0 | I12: =Progress!I8 -> 0 | J12: =IFERROR(IF(ISBLANK(G12),"",G12/C12),0) -> 0 | K12: =IFERROR(IF(ISBLANK(H12),"",H12/C12),0) -> 0 | L12: =IFERROR(IF(ISBLANK(I12),"",I12/C12),0) -> 0 | M12: =IFERROR(L12-K12,"") -> 0 | N12: =IFERROR(L12/K12,"") | O12: =Progress!K8 -> 4400 | P12: =IF(ISBLANK(O12),"",O12/$O$31) -> 0.030017738 | Q12: =Progress!M8 -> 0 | R12: =Progress!N8 -> 0 | S12: =IFERROR(IF(ISBLANK(Q12),"",Q12/O12),0) -> 0 | T12: =IFERROR(IF(ISBLANK(R12),"",R12/O12),0) -> 0 | U12: =Progress!O8 -> 4400 | V12: =Progress!P8 -> 4400 | W12: =IFERROR(IF(ISBLANK(U12),"",U12/O12),0) -> 1 | X12: =IFERROR(IF(ISBLANK(V12),"",V12/O12),0) -> 1 | Y12: =IFERROR(X12-W12,"") -> 0 | Z12: =IFERROR(X12/W12,"") -> 1
A13: =Progress!A9 -> Engineering Phase | C13: =Progress!C9 -> 494865 | D13: =IF(ISBLANK(C13),"",C13/$C$31) -> 0.029997534 | E13: =Progress!E9 -> 0 | F13: =Progress!F9 -> 0 | G13: =Progress!G9 -> 494865 | H13: =Progress!H9 -> 494865 | I13: =Progress!I9 -> 494865 | J13: =IFERROR(IF(ISBLANK(G13),"",G13/C13),0) -> 1 | K13: =IFERROR(IF(ISBLANK(H13),"",H13/C13),0) -> 1 | L13: =IFERROR(IF(ISBLANK(I13),"",I13/C13),0) -> 1 | M13: =IFERROR(L13-K13,"") -> 0 | N13: =IFERROR(L13/K13,"") -> 1 | O13: =Progress!K9 -> 7321 | P13: =IF(ISBLANK(O13),"",O13/$O$31) -> 0.049945422 | Q13: =Progress!M9 -> 0 | R13: =Progress!N9 -> 0 | S13: =IFERROR(IF(ISBLANK(Q13),"",Q13/O13),0) -> 0 | T13: =IFERROR(IF(ISBLANK(R13),"",R13/O13),0) -> 0 | U13: =Progress!O9 -> 7321 | V13: =Progress!P9 -> 7321 | W13: =IFERROR(IF(ISBLANK(U13),"",U13/O13),0) -> 1 | X13: =IFERROR(IF(ISBLANK(V13),"",V13/O13),0) -> 1 | Y13: =IFERROR(X13-W13,"") -> 0 | Z13: =IFERROR(X13/W13,"") -> 1
A14: =Progress!A10 -> Procurment | C14: =Progress!C10 -> 3299371 | D14: =IF(ISBLANK(C14),"",C14/$C$31) -> 0.19999999 | E14: =Progress!E10 -> 0 | F14: =Progress!F10 -> 10324.7 | G14: =Progress!G10 -> 3299371 | H14: =Progress!H10 -> 3299371 | I14: =Progress!I10 -> 3299371 | J14: =IFERROR(IF(ISBLANK(G14),"",G14/C14),0) -> 1 | K14: =IFERROR(IF(ISBLANK(H14),"",H14/C14),0) -> 1 | L14: =IFERROR(IF(ISBLANK(I14),"",I14/C14),0) -> 1 | M14: =IFERROR(L14-K14,"") -> 0 | N14: =IFERROR(L14/K14,"") -> 1 | O14: =Progress!K10 -> 17626 | P14: =IF(ISBLANK(O14),"",O14/$O$31) -> 0.12024833 | Q14: =Progress!M10 -> 0 | R14: =Progress!N10 -> 74 | S14: =IFERROR(IF(ISBLANK(Q14),"",Q14/O14),0) -> 0 | T14: =IFERROR(IF(ISBLANK(R14),"",R14/O14),0) -> 0.0041983434 | U14: =Progress!O10 -> 17626 | V14: =Progress!P10 -> 17626 | W14: =IFERROR(IF(ISBLANK(U14),"",U14/O14),0) -> 1 | X14: =IFERROR(IF(ISBLANK(V14),"",V14/O14),0) -> 1 | Y14: =IFERROR(X14-W14,"") -> 0 | Z14: =IFERROR(X14/W14,"") -> 1
A15: =Progress!A11 -> Construction phase | C15: =Progress!C11 -> 11052936 | D15: =IF(ISBLANK(C15),"",C15/$C$31) -> 0.67000257 | E15: =Progress!E11 -> 52113.6 | F15: =Progress!F11 -> 144090.88 | G15: =Progress!G11 -> 11052936 | H15: =Progress!H11 -> 11052936 | I15: =Progress!I11 -> 10978372 | J15: =IFERROR(IF(ISBLANK(G15),"",G15/C15),0) -> 1 | K15: =IFERROR(IF(ISBLANK(H15),"",H15/C15),0) -> 1 | L15: =IFERROR(IF(ISBLANK(I15),"",I15/C15),0) -> 0.9932539 | M15: =IFERROR(L15-K15,"") -> -0.0067461045 | N15: =IFERROR(L15/K15,"") -> 0.9932539 | O15: =Progress!K11 -> 109913 | P15: =IF(ISBLANK(O15),"",O15/$O$31) -> 0.74984991 | Q15: =Progress!M11 -> 244 | R15: =Progress!N11 -> 2590 | S15: =IFERROR(IF(ISBLANK(Q15),"",Q15/O15),0) -> 0.0022199376 | T15: =IFERROR(IF(ISBLANK(R15),"",R15/O15),0) -> 0.023564092 | U15: =Progress!O11 -> 109832 | V15: =Progress!P11 -> 108012 | W15: =IFERROR(IF(ISBLANK(U15),"",U15/O15),0) -> 0.99926305 | X15: =IFERROR(IF(ISBLANK(V15),"",V15/O15),0) -> 0.9827045 | Y15: =IFERROR(X15-W15,"") -> -0.016558551 | Z15: =IFERROR(X15/W15,"") -> 0.98342924
A16: =Progress!A12 -> site general works | C16: =Progress!C12 -> 1298122 | D16: =Progress!D12 -> 0.078689057 | E16: =Progress!E12 -> 0 | F16: =Progress!F12 -> 0 | G16: =Progress!H12 -> 1298122 | H16: =Progress!H12 -> 1298122 | I16: =Progress!I12 -> 1298122 | J16: =IFERROR(IF(ISBLANK(G16),"",G16/C16),0) -> 1 | K16: =IFERROR(IF(ISBLANK(H16),"",H16/C16),0) -> 1 | L16: =IFERROR(IF(ISBLANK(I16),"",I16/C16),0) -> 1 | M16: =IFERROR(L16-K16,"") -> 0 | N16: =IFERROR(L16/K16,"") -> 1 | O16: =Progress!K12 -> 5423 | P16: =Progress!L12 -> 0.036996862 | Q16: =Progress!M12 -> 0 | R16: =Progress!N12 -> 0 | S16: =IFERROR(IF(ISBLANK(Q16),"",Q16/O16),0) -> 0 | T16: =IFERROR(IF(ISBLANK(R16),"",R16/O16),0) -> 0 | U16: =Progress!O12 -> 5423 | V16: =Progress!P12 -> 5423 | W16: =IFERROR(IF(ISBLANK(U16),"",U16/O16),0) -> 1 | X16: =IFERROR(IF(ISBLANK(V16),"",V16/O16),0) -> 1 | Y16: =IFERROR(X16-W16,"") -> 0 | Z16: =IFERROR(X16/W16,"") -> 1
A17: =Progress!A13 -> Hunger -1 | C17: =Progress!C13 -> 3846587.2 | D17: =Progress!D13 -> 0.23317093 | E17: =Progress!E13 -> 52113.6 | F17: =Progress!F13 -> 33514.57 | G17: =Progress!H13 -> 3846587.2 | H17: =Progress!H13 -> 3846587.2 | I17: =Progress!I13 -> 3832084.2 | J17: =IFERROR(IF(ISBLANK(G17),"",G17/C17),0) -> 1 | K17: =IFERROR(IF(ISBLANK(H17),"",H17/C17),0) -> 1 | L17: =IFERROR(IF(ISBLANK(I17),"",I17/C17),0) -> 0.99622966 | M17: =IFERROR(L17-K17,"") -> -0.0037703396 | N17: =IFERROR(L17/K17,"") -> 0.99622966 | O17: =Progress!K13 -> 23347 | P17: =Progress!L13 -> 0.15927821 | Q17: =Progress!M13 -> 157 | R17: =Progress!N13 -> 320 | S17: =IFERROR(IF(ISBLANK(Q17),"",Q17/O17),0) -> 0.0067246327 | T17: =IFERROR(IF(ISBLANK(R17),"",R17/O17),0) -> 0.013706258 | U17: =Progress!O13 -> 23295 | V17: =Progress!P13 -> 23137 | W17: =IFERROR(IF(ISBLANK(U17),"",U17/O17),0) -> 0.99777273 | X17: =IFERROR(IF(ISBLANK(V17),"",V17/O17),0) -> 0.99100527 | Y17: =IFERROR(X17-W17,"") -> -0.0067674648 | Z17: =IFERROR(X17/W17,"") -> 0.99321743
A18: =Progress!A14 -> Hunger-2 | C18: =Progress!C14 -> 3851109 | D18: =Progress!D14 -> 0.23344503 | E18: =Progress!E14 -> 0 | F18: =Progress!F14 -> 33277.93 | G18: =Progress!H14 -> 3851109 | H18: =Progress!H14 -> 3851109 | I18: =Progress!I14 -> 3836609.7 | J18: =IFERROR(IF(ISBLANK(G18),"",G18/C18),0) -> 1 | K18: =IFERROR(IF(ISBLANK(H18),"",H18/C18),0) -> 1 | L18: =IFERROR(IF(ISBLANK(I18),"",I18/C18),0) -> 0.99623502 | M18: =IFERROR(L18-K18,"") -> -0.0037649778 | N18: =IFERROR(L18/K18,"") -> 0.99623502 | O18: =Progress!K14 -> 24765 | P18: =Progress!L14 -> 0.16895211 | Q18: =Progress!M14 -> 88 | R18: =Progress!N14 -> 350 | S18: =IFERROR(IF(ISBLANK(Q18),"",Q18/O18),0) -> 0.003553402 | T18: =IFERROR(IF(ISBLANK(R18),"",R18/O18),0) -> 0.014132849 | U18: =Progress!O14 -> 24736 | V18: =Progress!P14 -> 24529 | W18: =IFERROR(IF(ISBLANK(U18),"",U18/O18),0) -> 0.99882899 | X18: =IFERROR(IF(ISBLANK(V18),"",V18/O18),0) -> 0.99047042 | Y18: =IFERROR(X18-W18,"") -> -0.0083585706 | Z18: =IFERROR(X18/W18,"") -> 0.99163163
A19: =Progress!A15 -> Sephtic Tank | C19: =Progress!C15 -> 149552.06 | D19: =Progress!D15 -> 0.0090654887 | E19: =Progress!E15 -> 0 | F19: =Progress!F15 -> 0 | G19: =Progress!H15 -> 149552.06 | H19: =Progress!H15 -> 149552.06 | I19: =Progress!I15 -> 149552.06 | J19: =IFERROR(IF(ISBLANK(G19),"",G19/C19),0) -> 1 | K19: =IFERROR(IF(ISBLANK(H19),"",H19/C19),0) -> 1 | L19: =IFERROR(IF(ISBLANK(I19),"",I19/C19),0) -> 1 | M19: =IFERROR(L19-K19,"") -> 0 | N19: =IFERROR(L19/K19,"") -> 1 | O19: =Progress!K15 -> 7817 | P19: =Progress!L15 -> 0.05332924 | Q19: =Progress!M15 -> 0 | R19: =Progress!N15 -> 0 | S19: =IFERROR(IF(ISBLANK(Q19),"",Q19/O19),0) -> 0 | T19: =IFERROR(IF(ISBLANK(R19),"",R19/O19),0) -> 0 | U19: =Progress!O15 -> 7817 | V19: =Progress!P15 -> 7817 | W19: =IFERROR(IF(ISBLANK(U19),"",U19/O19),0) -> 1 | X19: =IFERROR(IF(ISBLANK(V19),"",V19/O19),0) -> 1 | Y19: =IFERROR(X19-W19,"") -> 0 | Z19: =IFERROR(X19/W19,"") -> 1
A20: =Progress!A16 -> Mosque -elec room-Toilets Works | C20: =Progress!C16 -> 396377.89 | D20: =Progress!D16 -> 0.024027481 | E20: =Progress!E16 -> 0 | F20: =Progress!F16 -> 20068.17 | G20: =Progress!H16 -> 396377.89 | H20: =Progress!H16 -> 396377.89 | I20: =Progress!I16 -> 386130.49 | J20: =IFERROR(IF(ISBLANK(G20),"",G20/C20),0) -> 1 | K20: =IFERROR(IF(ISBLANK(H20),"",H20/C20),0) -> 1 | L20: =IFERROR(IF(ISBLANK(I20),"",I20/C20),0) -> 0.9741474 | M20: =IFERROR(L20-K20,"") -> -0.025852602 | N20: =IFERROR(L20/K20,"") -> 0.9741474 | O20: =Progress!K16 -> 15308 | P20: =Progress!L16 -> 0.10443444 | Q20: =Progress!M16 -> 0 | R20: =Progress!N16 -> 671 | S20: =IFERROR(IF(ISBLANK(Q20),"",Q20/O20),0) -> 0 | T20: =IFERROR(IF(ISBLANK(R20),"",R20/O20),0) -> 0.04383329 | U20: =Progress!O16 -> 15308 | V20: =Progress!P16 -> 14842 | W20: =IFERROR(IF(ISBLANK(U20),"",U20/O20),0) -> 1 | X20: =IFERROR(IF(ISBLANK(V20),"",V20/O20),0) -> 0.9695584 | Y20: =IFERROR(X20-W20,"") -> -0.030441599 | Z20: =IFERROR(X20/W20,"") -> 0.9695584
A21: =Progress!A17 -> GRB Tank | C21: =Progress!C17 -> 163749.6 | D21: =Progress!D17 -> 0.0099261096 | E21: =Progress!E17 -> 0 | F21: =Progress!F17 -> 0 | G21: =Progress!H17 -> 163749.6 | H21: =Progress!H17 -> 163749.6 | I21: =Progress!I17 -> 163749.6 | J21: =IFERROR(IF(ISBLANK(G21),"",G21/C21),0) -> 1 | K21: =IFERROR(IF(ISBLANK(H21),"",H21/C21),0) -> 1 | L21: =IFERROR(IF(ISBLANK(I21),"",I21/C21),0) -> 1 | M21: =IFERROR(L21-K21,"") -> 0 | N21: =IFERROR(L21/K21,"") -> 1 | O21: =Progress!K17 -> 9922 | P21: =Progress!L17 -> 0.067689999 | Q21: =Progress!M17 -> 0 | R21: =Progress!N17 -> 0 | S21: =IFERROR(IF(ISBLANK(Q21),"",Q21/O21),0) -> 0 | T21: =IFERROR(IF(ISBLANK(R21),"",R21/O21),0) -> 0 | U21: =Progress!O17 -> 9922 | V21: =Progress!P17 -> 9922 | W21: =IFERROR(IF(ISBLANK(U21),"",U21/O21),0) -> 1 | X21: =IFERROR(IF(ISBLANK(V21),"",V21/O21),0) -> 1 | Y21: =IFERROR(X21-W21,"") -> 0 | Z21: =IFERROR(X21/W21,"") -> 1
A22: =Progress!A18 -> Pump room | C22: =Progress!C18 -> 389712.84 | D22: =Progress!D18 -> 0.023623462 | E22: =Progress!E18 -> 0 | F22: =Progress!F18 -> 2664.93 | G22: =Progress!H18 -> 389712.84 | H22: =Progress!H18 -> 389712.84 | I22: =Progress!I18 -> 387774.89 | J22: =IFERROR(IF(ISBLANK(G22),"",G22/C22),0) -> 1 | K22: =IFERROR(IF(ISBLANK(H22),"",H22/C22),0) -> 1 | L22: =IFERROR(IF(ISBLANK(I22),"",I22/C22),0) -> 0.99502724 | M22: =IFERROR(L22-K22,"") -> -0.004972764 | N22: =IFERROR(L22/K22,"") -> 0.99502724 | O22: =Progress!K18 -> 7698 | P22: =Progress!L18 -> 0.052517397 | Q22: =Progress!M18 -> 0 | R22: =Progress!N18 -> 192 | S22: =IFERROR(IF(ISBLANK(Q22),"",Q22/O22),0) -> 0 | T22: =IFERROR(IF(ISBLANK(R22),"",R22/O22),0) -> 0.024941543 | U22: =Progress!O18 -> 7698 | V22: =Progress!P18 -> 7313 | W22: =IFERROR(IF(ISBLANK(U22),"",U22/O22),0) -> 1 | X22: =IFERROR(IF(ISBLANK(V22),"",V22/O22),0) -> 0.94998701 | Y22: =IFERROR(X22-W22,"") -> -0.05001299 | Z22: =IFERROR(X22/W22,"") -> 0.94998701
A23: =Progress!A19 -> External WORKS-MEP | C23: =Progress!C19 -> 581705.66 | D23: =Progress!D19 -> 0.035261608 | E23: =Progress!E19 -> 0 | F23: =Progress!F19 -> 3195.27 | G23: =Progress!H19 -> 581705.66 | H23: =Progress!H19 -> 581705.66 | I23: =Progress!I19 -> 570319.85 | J23: =IFERROR(IF(ISBLANK(G23),"",G23/C23),0) -> 1 | K23: =IFERROR(IF(ISBLANK(H23),"",H23/C23),0) -> 1 | L23: =IFERROR(IF(ISBLANK(I23),"",I23/C23),0) -> 0.98042685 | M23: =IFERROR(L23-K23,"") -> -0.019573146 | N23: =IFERROR(L23/K23,"") -> 0.98042685 | O23: =Progress!K19 -> 6008 | P23: =Progress!L19 -> 0.040987856 | Q23: =Progress!M19 -> 0 | R23: =Progress!N19 -> 7 | S23: =IFERROR(IF(ISBLANK(Q23),"",Q23/O23),0) -> 0 | T23: =IFERROR(IF(ISBLANK(R23),"",R23/O23),0) -> 0.0011651132 | U23: =Progress!O19 -> 6008 | V23: =Progress!P19 -> 5985 | W23: =IFERROR(IF(ISBLANK(U23),"",U23/O23),0) -> 1 | X23: =IFERROR(IF(ISBLANK(V23),"",V23/O23),0) -> 0.99617177 | Y23: =IFERROR(X23-W23,"") -> -0.003828229 | Z23: =IFERROR(X23/W23,"") -> 0.99617177
A24: =Progress!A20 -> External Works landscape | C24: =Progress!C20 -> 376019.58 | D24: =Progress!D20 -> 0.022793409 | E24: =Progress!E20 -> 0 | F24: =Progress!F20 -> 51370.56 | G24: =Progress!H20 -> 376019.58 | H24: =Progress!H20 -> 376019.58 | I24: =Progress!I20 -> 354028.77 | J24: =IFERROR(IF(ISBLANK(G24),"",G24/C24),0) -> 1 | K24: =IFERROR(IF(ISBLANK(H24),"",H24/C24),0) -> 1 | L24: =IFERROR(IF(ISBLANK(I24),"",I24/C24),0) -> 0.94151685 | M24: =IFERROR(L24-K24,"") -> -0.058483151 | N24: =IFERROR(L24/K24,"") -> 0.94151685 | O24: =Progress!K20 -> 9626 | P24: =Progress!L20 -> 0.065670624 | Q24: =Progress!M20 -> 0 | R24: =Progress!N20 -> 1050 | S24: =IFERROR(IF(ISBLANK(Q24),"",Q24/O24),0) -> 0 | T24: =IFERROR(IF(ISBLANK(R24),"",R24/O24),0) -> 0.10907958 | U24: =Progress!O20 -> 9626 | V24: =Progress!P20 -> 9045 | W24: =IFERROR(IF(ISBLANK(U24),"",U24/O24),0) -> 1 | X24: =IFERROR(IF(ISBLANK(V24),"",V24/O24),0) -> 0.93964263 | Y24: =IFERROR(X24-W24,"") -> -0.060357365 | Z24: =IFERROR(X24/W24,"") -> 0.93964263
A25: =Progress!A21 -> Testing and comissiong | C25: =Progress!C21 -> 1649684 | D25: =IF(ISBLANK(C25),"",C25/$C$31) -> 0.099999904 | E25: =Progress!E21 -> 259325.32 | F25: =Progress!F21 -> 41242.1 | G25: =Progress!G21 -> 1574698.4 | H25: =Progress!H21 -> 1574698.4 | I25: =Progress!I21 -> 1422852.4 | J25: =IFERROR(IF(ISBLANK(G25),"",G25/C25),0) -> 0.95454545 | K25: =IFERROR(IF(ISBLANK(H25),"",H25/C25),0) -> 0.95454545 | L25: =IFERROR(IF(ISBLANK(I25),"",I25/C25),0) -> 0.8625 | M25: =IFERROR(L25-K25,"") -> -0.092045452 | N25: =IFERROR(L25/K25,"") -> 0.90357143 | O25: =Progress!K21 -> 7320 | P25: =IF(ISBLANK(O25),"",O25/$O$31) -> 0.0499386 | Q25: =Progress!M21 -> 1150 | R25: =Progress!N21 -> 183 | S25: =IFERROR(IF(ISBLANK(Q25),"",Q25/O25),0) -> 0.15710383 | T25: =IFERROR(IF(ISBLANK(R25),"",R25/O25),0) -> 0.025 | U25: =Progress!O21 -> 6987 | V25: =Progress!P21 -> 6314 | W25: =IFERROR(IF(ISBLANK(U25),"",U25/O25),0) -> 0.9545082 | X25: =IFERROR(IF(ISBLANK(V25),"",V25/O25),0) -> 0.86256831 | Y25: =IFERROR(X25-W25,"") -> -0.091939891 | Z25: =IFERROR(X25/W25,"") -> 0.90367826
A26: =Progress!A22 -> Close Out | C26: =Progress!C22 -> 0 | D26: =IF(ISBLANK(C26),"",C26/$C$31) -> 0 | E26: =Progress!E22 -> 0 | F26: =Progress!F22 -> 0 | G26: =Progress!G22 -> 0 | H26: =Progress!H22 -> 0 | I26: =Progress!I22 -> 0 | J26: =IFERROR(IF(ISBLANK(G26),"",G26/C26),0) -> 0 | K26: =IFERROR(IF(ISBLANK(H26),"",H26/C26),0) -> 0 | L26: =IFERROR(IF(ISBLANK(I26),"",I26/C26),0) -> 0 | M26: =IFERROR(L26-K26,"") -> 0 | N26: =IFERROR(L26/K26,"") | O26: =Progress!K22 -> 0 | P26: =IF(ISBLANK(O26),"",O26/$O$31) -> 0 | Q26: =Progress!M22 -> 0 | R26: =Progress!N22 -> 0 | S26: =IFERROR(IF(ISBLANK(Q26),"",Q26/O26),0) -> 0 | T26: =IFERROR(IF(ISBLANK(R26),"",R26/O26),0) -> 0 | U26: =Progress!O22 -> 0 | V26: =Progress!P22 -> 0 | W26: =IFERROR(IF(ISBLANK(U26),"",U26/O26),0) -> 0 | X26: =IFERROR(IF(ISBLANK(V26),"",V26/O26),0) -> 0 | Y26: =IFERROR(X26-W26,"") -> 0 | Z26: =IFERROR(X26/W26,"")
D27: =IF(ISBLANK(C27),"",C27/$C$31) | J27: =IFERROR(IF(ISBLANK(G27),"",G27/C27),0) | K27: =IFERROR(IF(ISBLANK(H27),"",H27/C27),0) | L27: =IFERROR(IF(ISBLANK(I27),"",I27/C27),0) | M27: =IFERROR(L27-K27,"") | N27: =IFERROR(L27/K27,"") | S27: =IFERROR(IF(ISBLANK(Q27),"",Q27/O27),0) | T27: =IFERROR(IF(ISBLANK(R27),"",R27/O27),0) | W27: =IFERROR(IF(ISBLANK(U27),"",U27/O27),0) | X27: =IFERROR(IF(ISBLANK(V27),"",V27/O27),0) | Y27: =IFERROR(X27-W27,"") | Z27: =IFERROR(X27/W27,"")
D28: =IF(ISBLANK(C28),"",C28/$C$31) | J28: =IFERROR(IF(ISBLANK(G28),"",G28/C28),0) | K28: =IFERROR(IF(ISBLANK(H28),"",H28/C28),0) | L28: =IFERROR(IF(ISBLANK(I28),"",I28/C28),0) | M28: =IFERROR(L28-K28,"") | N28: =IFERROR(L28/K28,"") | S28: =IFERROR(IF(ISBLANK(Q28),"",Q28/O28),0) | T28: =IFERROR(IF(ISBLANK(R28),"",R28/O28),0) | W28: =IFERROR(IF(ISBLANK(U28),"",U28/O28),0) | X28: =IFERROR(IF(ISBLANK(V28),"",V28/O28),0) | Y28: =IFERROR(X28-W28,"") | Z28: =IFERROR(X28/W28,"")
D29: =IF(ISBLANK(C29),"",C29/$C$31) | J29: =IFERROR(IF(ISBLANK(G29),"",G29/C29),0) | K29: =IFERROR(IF(ISBLANK(H29),"",H29/C29),0) | L29: =IFERROR(IF(ISBLANK(I29),"",I29/C29),0) | M29: =IFERROR(L29-K29,"") | N29: =IFERROR(L29/K29,"") | S29: =IFERROR(IF(ISBLANK(Q29),"",Q29/O29),0) | T29: =IFERROR(IF(ISBLANK(R29),"",R29/O29),0) | W29: =IFERROR(IF(ISBLANK(U29),"",U29/O29),0) | X29: =IFERROR(IF(ISBLANK(V29),"",V29/O29),0) | Y29: =IFERROR(X29-W29,"") | Z29: =IFERROR(X29/W29,"")
D30: =IF(ISBLANK(C30),"",C30/$C$31) | J30: =IFERROR(IF(ISBLANK(G30),"",G30/C30),0) | K30: =IFERROR(IF(ISBLANK(H30),"",H30/C30),0) | L30: =IFERROR(IF(ISBLANK(I30),"",I30/C30),0) | M30: =IFERROR(L30-K30,"") | N30: =IFERROR(L30/K30,"") | S30: =IFERROR(IF(ISBLANK(Q30),"",Q30/O30),0) | T30: =IFERROR(IF(ISBLANK(R30),"",R30/O30),0) | W30: =IFERROR(IF(ISBLANK(U30),"",U30/O30),0) | X30: =IFERROR(IF(ISBLANK(V30),"",V30/O30),0) | Y30: =IFERROR(X30-W30,"") | Z30: =IFERROR(X30/W30,"")
B31: Total | C31: =SUM(C13:C15,C25) -> 16496856 | D31: =SUM(D13:D15,D25) -> 1 | E31: =SUM(E13:E15,E25) -> 311438.92 | F31: =SUM(F13:F15,F25) -> 195657.68 | G31: =SUM(G13:G15,G25) -> 16421870 | H31: =SUM(H13:H15,H25) -> 16421870 | I31: =SUM(I13:I15,I25) -> 16195460 | J31: =IFERROR(IF(ISBLANK(G31),"",G31/C31),0) -> 0.99545455 | K31: =IFERROR(IF(ISBLANK(H31),"",H31/C31),0) -> 0.99545455 | L31: =IFERROR(IF(ISBLANK(I31),"",I31/C31),0) -> 0.98173011 | M31: =+L31-K31 -> -0.013724444 | N31: =L31/K31 -> 0.98621289 | O31: =SUM(O12:O15,O25) -> 146580 | P31: =SUM(P12:P15,P25) -> 1 | Q31: =SUM(Q13:Q15,Q25) -> 1394 | R31: =SUM(R13:R15,R25) -> 2847 | S31: =IFERROR(IF(ISBLANK(Q31),"",Q31/O31),0) -> 0.0095101651 | T31: =IFERROR(IF(ISBLANK(R31),"",R31/O31),0) -> 0.019422841 | U31: =SUM(U12:U15,U25) -> 146166 | V31: =SUM(V12:V15,V25) -> 143673 | W31: =IFERROR(IF(ISBLANK(U31),"",U31/O31),0) -> 0.9971756 | X31: =IFERROR(IF(ISBLANK(V31),"",V31/O31),0) -> 0.98016783 | Y31: =+X31-W31 -> -0.017007777 | Z31: =X31/W31 -> 0.98294405
AA32: Construction Milestones
AA33: Item No. | AB33: Milestones | AD33: Original (Baseline) | AE33: Latest Plan | AF33: Forecast | AG33: Status | AH33: Days Change
AA34: =+Milestones!A4 -> 1 | AB34: =+Milestones!B4 -> Award Date | AD34: =+Milestones!C4 -> 45945 | AE34: =+Milestones!D4 -> 45945 | AF34: =+Milestones!E4 -> 45945 | AG34: =+Milestones!F4 -> A | AH34: =+Milestones!G4 -> 0
AA35: =+Milestones!A5 -> 2 | AB35: =+Milestones!B5 -> Contract Sign Date | AD35: =+Milestones!C5 -> 45977 | AE35: =+Milestones!D5 -> 45977 | AF35: =+Milestones!E5 -> 45977 | AG35: =+Milestones!F5 -> A | AH35: =+Milestones!G5 -> 0
AA36: =+Milestones!A6 -> 3 | AB36: =+Milestones!B6 -> Site Handover Date | AD36: =+Milestones!C6 -> 45988 | AE36: =+Milestones!D6 -> 45988 | AF36: =+Milestones!E6 -> 45988 | AG36: =+Milestones!F6 -> A | AH36: =+Milestones!G6 -> 0
AA37: =+Milestones!A7 -> 4 | AB37: =+Milestones!B7 -> Complete Mobilization | AD37: =+Milestones!C7 -> 46019 | AE37: =+Milestones!D7 -> 46019 | AF37: =+Milestones!E7 -> 46019 | AG37: =+Milestones!F7 -> A | AH37: =+Milestones!G7 -> 0
AA38: =+Milestones!A10 -> 7 | AB38: =+Milestones!B10 -> Complete Earthworks | AD38: =+Milestones!C10 -> 46103 | AE38: =+Milestones!D10 -> 46116 | AF38: =+Milestones!E10 -> 46116 | AG38: =+Milestones!F10 -> F | AH38: =+Milestones!G10 -> 0
AA39: =+Milestones!A11 -> 8 | AB39: =+Milestones!B11 -> Complete Civil & Arch Works | AD39: =+Milestones!C11 -> 45854 | AE39: =+Milestones!D11 -> 46340 | AF39: =+Milestones!E11 -> 46306 | AG39: =+Milestones!F11 -> F | AH39: =+Milestones!G11 -> 34
AA40: =+Milestones!A12 -> 9 | AB40: =+Milestones!B12 -> Complete Electrical Works | AD40: =+Milestones!C12 -> 45902 | AE40: =+Milestones!D12 -> 46333 | AF40: =+Milestones!E12 -> 46312 | AG40: =+Milestones!F12 -> F | AH40: =+Milestones!G12 -> 21
AA41: =+Milestones!A13 -> 10 | AB41: =+Milestones!B13 -> Complete Mechanical Works | AD41: =+Milestones!C13 -> 45926 | AE41: =+Milestones!D13 -> 46358 | AF41: =+Milestones!E13 -> 46324 | AG41: =+Milestones!F13 -> F | AH41: =+Milestones!G13 -> 34
...

Sheet General Information
A1: Weekly Progress Report - Construction Projects | K1: Data Date | L1: 46286
A2: Contract General Information
A3: Project Name | C3: Factories Low-process Unit (HAFR Al Batin)
A4: Project ID | C4: HFR1-05-03
A5: Contractor | C5: SOROH AL KHAIR CONTRACTING CO.
A6: Consultant | C6: EGIS
A7: Stage | C7: Construction
A8: Status | C8: Active
A9: Modon PM | C9: Eng. Mohammed Al Essa
A11: Key Dates
A12: Contract Award Date | C12: =Milestones!C4 -> 45945
A13: Contract Sign Date | C13: =Milestones!C5 -> 45977
A14: Site Handover Date | C14: =Milestones!C6 -> 45988
A15: Original Completion | C15: =Milestones!C15 -> 46291
A16: Contract Award Date (Hijri) | C16: =C12 -> 45945
A17: Contract Sign Date (Hijri) | C17: =C13 -> 45977
A18: Site Handover Date (Hijri) | C18: =C14 -> 45988
A19: Original Completion (Hijri) | C19: =C15 -> 46291
A20: Revised Completion Date | C20: =Milestones!C15 -> 46291
A21: Committed Completion Date | C21: =Milestones!E14 -> 46324
A22: Forecast Completion | C22: =Milestones!E15 -> 46333
A23: Variance | C23: =C20-C22 -> -42
A25: Key Project Submittals | C25: Submission Date | D25: Days taken to approve orginal plan from site handover date
A26: Quality Plan submission | C26: 46032 | D26: =C27-C14 -> 118
A27: Quality Plan approval | C27: 46106
A28: Quality Plan Last Update | C28: 46106
A30: Safety Plan submission | C30: 46021 | D30: =C31-C14 -> 299
A31: Safety Plan approval | C31: =TODAY() -> 46287
A32: Safety Plan Last Update
A34: Risk Management Plan submission | C34: 46021 | D34: =C35-C14 -> 299
A35: Risk Management Plan approval | C35: =TODAY() -> 46287
A36: Risk Management Plan Last Update
A38: Baseline Schedule submission | C38: 46020 | D38: =C38-C14 -> 32
A39: Baseline Schedule approval | C39: 46088
A40: No of Schedule Versions | C40: 2
A41: Last Recovery Schedule Approval Date | C41: 46088
A43: BOQ submission | C43: 46023 | D43: =C43-C14 -> 35
A44: BOQ approval | C44: 46158
A45: No of Approved Version of BOQ | C45: 0
A47: Construction Plan submission | C47: =TODAY() -> 46287 | D47: =C47-C14 -> 299
...

Sheet Progress
A1: Project Scope Statement | B1: The Project scope of work to construct a Factories of low process unit (Hafr Al Batin) industrial city that refer to specific tasks and activities involved in a project. This typically includes activities such as site preparation, Excavation, Foundation work, Structural construction work, Installation of utilities, Finishing works, Electrical Work, Mechanical Works and Landscaping. The scope outlines what will be done and by whom and within the planned timeframe. | S1: ='General Information'!$K$1 -> Data Date | T1: ='General Information'!L1 -> 46286
A4: Earned Value Progress (SAR) | K4: Physical Progress (Effort)
A5: WBS | C5: BOQ Value (SAR) | D5: % Wt. | E5: Weekly (SAR) | H5: To Date (SAR) | K5: Budgeted | L5: % Wt. | M5: Weekly Physical Progress | O5: To Date Physical Progress
E6: Planned | F6: Earned | G6: Original Plan | H6: Planned | I6: Earned | K6: (Manhours) | M6: Planned | N6: Earned | O6: Planned | P6: Earned
A7: Project Milestones | C7: 0 | D7: =IF(ISBLANK(C7),"",C7/$C$23) -> 0 | E7: 0 | F7: 0 | G7: 0 | H7: 0 | I7: 0 | K7: 0 | L7: =IF(ISBLANK(K7),"",K7/$K$23) -> 0 | M7: 0 | N7: 0 | O7: 0 | P7: 0
A8: Mobilization | C8: 0 | D8: =IF(ISBLANK(C8),"",C8/$C$23) -> 0 | E8: 0 | F8: 0 | G8: 0 | H8: 0 | I8: 0 | K8: 4400 | L8: =IF(ISBLANK(K8),"",K8/$K$23) -> 0.030017738 | M8: 0 | O8: 4400 | P8: 4400
A9: Engineering Phase | B9: premilinary submittals | C9: 494865 | D9: =IF(ISBLANK(C9),"",C9/$C$23) -> 0.029997534 | G9: 494865 | H9: 494865 | I9: 494865 | K9: 7321 | L9: =IF(ISBLANK(K9),"",K9/$K$23) -> 0.049945422 | M9: 0 | O9: 7321 | P9: 7321
A10: Procurment | B10: premilinary Approve | C10: 3299371 | D10: =IF(ISBLANK(C10),"",C10/$C$23) -> 0.19999999 | F10: 10324.7 | G10: 3299371 | H10: 3299371 | I10: 3299371 | K10: 17626 | L10: =IF(ISBLANK(K10),"",K10/$K$23) -> 0.12024833 | N10: 74 | O10: 17626 | P10: 17626
A11: Construction phase | C11: 11052936 | D11: =IF(ISBLANK(C11),"",C11/$C$23) -> 0.67000257 | E11: 52113.6 | F11: 144090.88 | G11: 11052936 | H11: 11052936 | I11: 10978372 | K11: 109913 | L11: =IF(ISBLANK(K11),"",K11/$K$23) -> 0.74984991 | M11: 244 | N11: 2590 | O11: 109832 | P11: 108012
A12: site general works | C12: 1298122 | D12: =IF(ISBLANK(C12),"",C12/$C$23) -> 0.078689057 | H12: 1298122 | I12: 1298122 | K12: 5423 | L12: =IF(ISBLANK(K12),"",K12/$K$23) -> 0.036996862 | O12: 5423 | P12: 5423
A13: Hunger -1 | C13: 3846587.2 | D13: =IF(ISBLANK(C13),"",C13/$C$23) -> 0.23317093 | E13: 52113.6 | F13: 33514.57 | H13: 3846587.2 | I13: 3832084.2 | K13: 23347 | L13: =IF(ISBLANK(K13),"",K13/$K$23) -> 0.15927821 | M13: 157 | N13: 320 | O13: 23295 | P13: 23137
A14: Hunger-2 | C14: 3851109 | D14: =IF(ISBLANK(C14),"",C14/$C$23) -> 0.23344503 | F14: 33277.93 | H14: 3851109 | I14: 3836609.7 | K14: 24765 | L14: =IF(ISBLANK(K14),"",K14/$K$23) -> 0.16895211 | M14: 88 | N14: 350 | O14: 24736 | P14: 24529
A15: Sephtic Tank | C15: 149552.06 | D15: =IF(ISBLANK(C15),"",C15/$C$23) -> 0.0090654887 | H15: 149552.06 | I15: 149552.06 | K15: 7817 | L15: =IF(ISBLANK(K15),"",K15/$K$23) -> 0.05332924 | O15: 7817 | P15: 7817
A16: Mosque -elec room-Toilets Works | C16: 396377.89 | D16: =IF(ISBLANK(C16),"",C16/$C$23) -> 0.024027481 | F16: 20068.17 | H16: 396377.89 | I16: 386130.49 | K16: 15308 | L16: =IF(ISBLANK(K16),"",K16/$K$23) -> 0.10443444 | N16: 671 | O16: 15308 | P16: 14842
A17: GRB Tank | C17: 163749.6 | D17: =IF(ISBLANK(C17),"",C17/$C$23) -> 0.0099261096 | H17: 163749.6 | I17: 163749.6 | K17: 9922 | L17: =IF(ISBLANK(K17),"",K17/$K$23) -> 0.067689999 | O17: 9922 | P17: 9922
A18: Pump room | C18: 389712.84 | D18: =IF(ISBLANK(C18),"",C18/$C$23) -> 0.023623462 | F18: 2664.93 | H18: 389712.84 | I18: 387774.89 | K18: 7698 | L18: =IF(ISBLANK(K18),"",K18/$K$23) -> 0.052517397 | N18: 192 | O18: 7698 | P18: 7313
A19: External WORKS-MEP | C19: 581705.66 | D19: =IF(ISBLANK(C19),"",C19/$C$23) -> 0.035261608 | F19: 3195.27 | H19: 581705.66 | I19: 570319.85 | K19: 6008 | L19: =IF(ISBLANK(K19),"",K19/$K$23) -> 0.040987856 | N19: 7 | O19: 6008 | P19: 5985
A20: External Works landscape | C20: 376019.58 | D20: =IF(ISBLANK(C20),"",C20/$C$23) -> 0.022793409 | F20: 51370.56 | G20: 0 | H20: 376019.58 | I20: 354028.77 | K20: 9626 | L20: =IF(ISBLANK(K20),"",K20/$K$23) -> 0.065670624 | N20: 1050 | O20: 9626 | P20: 9045
A21: Testing and comissiong | C21: 1649684 | D21: =IF(ISBLANK(C21),"",C21/$C$23) -> 0.099999904 | E21: 259325.32 | F21: 41242.1 | G21: 1574698.4 | H21: 1574698.4 | I21: 1422852.4 | K21: 7320 | L21: =IF(ISBLANK(K21),"",K21/$K$23) -> 0.0499386 | M21: 1150 | N21: 183 | O21: 6987 | P21: 6314
A22: Close Out | C22: 0 | D22: =IF(ISBLANK(C22),"",C22/$C$23) -> 0 | E22: 0 | F22: 0 | G22: 0 | H22: 0 | I22: 0 | K22: 0 | L22: =IF(ISBLANK(K22),"",K22/$K$23) -> 0 | M22: 0 | N22: 0 | O22: 0 | P22: 0
B23: Total | C23: =SUM(C7:C11,C21,C22) -> 16496856 | D23: =SUM(D7:D11,D21,D22) -> 1 | E23: =SUM(E7:E11,E21,E22) -> 311438.92 | F23: =SUM(F7:F11,F21,F22) -> 195657.68 | G23: =SUM(G7:G11,G21,G22) -> 16421870 | H23: =SUM(H7:H11,H21,H22) -> 16421870 | I23: =SUM(I7:I11,I21,I22) -> 16195460 | K23: =SUM(K7:K11,K21,K22) -> 146580 | L23: =SUM(L7:L11,L21,L22) -> 1 | M23: =SUM(M7:M11,M21,M22) -> 1394 | N23: =SUM(N7:N11,N21,N22) -> 2847 | O23: =SUM(O7:O11,O21,O22) -> 146166 | P23: =SUM(P7:P11,P21,P22) -> 143673
E24: =E23/$C$23 -> 0.018878683 | F24: =F23/$C$23 -> 0.011860301 | G24: =G23/$C$23 -> 0.99545455 | H24: =H23/$C$23 -> 0.99545455 | I24: =I23/$C$23 -> 0.98173011 | M24: =M23/$K$23 -> 0.0095101651 | N24: =N23/$K$23 -> 0.019422841 | O24: =O23/$K$23 -> 0.9971756 | P24: =P23/$K$23 -> 0.98016783
M28: `

Sheet Weekly Photos
B1: Date | C1: ='Weekly Progress Report'!AG1 -> 46286
B4: Commsission of Panel Board for Building 2 | L4: Installation of Water draiange from roof top
B23: Installation of Exaust Fan for Building 2 | L23: Installation of Epoxy Paint - Building 2
B42: Installation of Traffic Signs | L42: Installation of Road Markings Work
B60: Installation of Cladding for Building 2 | L60: Asphlat work 2nd layer for Road Work

Sheet FIR Summary
A2: Project Name | D2: Factories Low-process Unit (HAFR Al Batin)
A3: Project ID | D3: HFR1-05-03 | E3: Project Budget | G3: 16496856
A4: Total FIR Approved Value (Cumulative) | D4: ='FIR from Begining up to date '!K328 -> 11743680 | E4: Remaining FIRs Value (Cumulative) | G4: =G3-D4 -> 4753175.8
A5: Date Period | D5: 46279 | E5: To | G5: =D5+7 -> 46286
A7: BOQ Item # | B7: BOQ Description | C7: FIR / DATE | D7: FIR # | E7: FIR Description | F7: Status | G7: Unit Rate | H7: Current Period Quantity | I7: Progress (%) | J7: Total (SAR) | K7: Remarks
A9: 2.2.4 | B9: Supply and execute subgrade material up to the full width of the road as per specifications and drawings | C9: 46253 | D9: HFR1-05-003-SAK-TS9-1FIR-SUV-0144-00 | E9: Supply and execute subgrade material Layer-2 (15cm Sub Base), as per highlighted drawing. | F9: Approved | G9: 66 | H9: 1047.6555 | I9: 1 | J9: 69145.263
A10: 5.1 | B10: Supply and install steel ladder with safety cage including all necessary fixings, fixtures, painting all as per drawings and specifications. (Height = 5.5m) | D10: HFR1-05-003-SAK-TS9-1-FIR- ARC-0074-00 | E10: Supply and install steel ladder with safety cage including all necessary fixings, fixtures. | F10: Approved | G10: 5940 | H10: 2 | I10: 1 | J10: 11880
A11: 8.1.1 | B11: Supply and install (D6) 3000*3500mm galvanized steel heavy duty industrial isolated type roll up shutter door finished with polyurethane coating, with automatic and manual control system, as per manufacturer specification and approved by the Client, complete with all accessories and fittings, and as per door schedule and specifications | D11: HFR1-05-003-SAK-TS9-1-FIR-ARC-0122-00 | F11: Approved | G11: 15510 | H11: 24 | I11: 0.35 | J11: 130284
A12: 8.1.2 | B12: Supply and install fire rated 45 min. (D5) 1000*2200mm single leaf steel door with door construction type C with hardware set type HW2 paint finish as per manufacturer detail and approved by the Client with complete accessories as per door schedule, drawings and specification | D12: HFR1-05-003-SAK-TS9-1-FIR-ARC-0123-00 | F12: Approved | G12: 2750 | H12: 24 | I12: 0.35 | J12: 23100
A13: 8.1.3 | B13: Supply and install (D2) 1000*2200 mm single leaf galvanized steel door with door construction type B with hardware set type HW1 paint finish as per manufacturer detail and approved by the Client with complete accessories as per door/window schedule and as per drawings and specification. | C13: 46254 | D13: HFR1-05-003-SAK-TS9-1-FIR- ARC-0120-00 | E13: Supply and install (D2) 1000*2200 mm single leaf galvanized steel door with door construction type B with hardware set type HW1 paint finish at Building-1 (axis A-N/1x3), as per highlighted drawing. | F13: Approved | G13: 3355 | H13: 2 | I13: 1 | J13: 6710
A14: 8.1.4 | B14: Supply and install (D3) 800*2200 mm single leaf semi solid wood door with door construction type B with hardware set type HW1 paint finish as per manufacturer detail and approved by the Client with complete accessories as per door/window schedule and as per drawings and specification. | C14: 46254 | D14: HFR1-05-003-SAK-TS9-1-FIR- ARC-0121-00 | E14: Supply and install (D3) 800*2200 mm single leaf semi solid wood door with door construction type B with hardware set type HW1 paint finish at Building-1 (axis A-N/1x3), as per highlighted drawing. | F14: Approved | G14: 2896 | H14: 2 | I14: 1 | J14: 5792
A15: 8.1.4 | B15: Supply and install (D3) 800*2200 mm single leaf semi solid wood door with door construction type B with hardware set type HW1 paint finish as per manufacturer detail and approved by the Client with complete accessories as per door/window schedule and as per drawings and specification. | C15: 46254 | D15: HFR1-05-003-SAK-TS9-1-FIR- ARC-0119-00 | E15: Supply and install (D3) 800*2200 mm single leaf semi solid wood door with door construction type B with hardware set type HW1 paint finish at Building-2 (axis A-N/1x3), as per highlighted drawing. | F15: Approved | G15: 2896 | H15: 2 | I15: 1 | J15: 5792
A16: 9.2.8 | B16: Supply and install phenolic partitions with doors for toilets including accessories, fixations, fittings, and all the required works as shown in the drawings and specification with approved quality by the Client | D16: HFR1-05-003-SAK-TS9-1-FIR- ARC-0116-00 | F16: Approved | G16: 660 | H16: 65 | I16: 1 | J16: 42900
J17: =IF(F17="Approved",G17*H17*I17,0) -> 0
J18: =IF(F18="Approved",G18*H18*I18,0) -> 0
J19: =IF(F19="Approved",G19*H19*I19,0) -> 0
J20: =IF(F20="Approved",G20*H20*I20,0) -> 0
J21: =IF(F21="Approved",G21*H21*I21,0) -> 0
J22: =IF(F22="Approved",G22*H22*I22,0) -> 0
J23: =IF(F23="Approved",G23*H23*I23,0) -> 0
J24: =IF(F24="Approved",G24*H24*I24,0) -> 0
J25: =IF(F25="Approved",G25*H25*I25,0) -> 0
J26: =IF(F26="Approved",G26*H26*I26,0) -> 0
J27: =IF(F27="Approved",G27*H27*I27,0) -> 0
J28: =IF(F28="Approved",G28*H28*I28,0) -> 0
... J34: =IF(F34="Approved",G34*H34*I34,0) -> 0
C43: Total Excuted Amount | J43: =SUM(J9:J42) -> 295603.26

Sheet Quality
B2: QC OBSERVATIONS CHECKLIST
BB4: 46069
B6: Project No. | E6: HFR1-05-03 | K6: OBS No. | O6: 14 | U6: Inspection Day: | X6: 46286
B8: Project | E8: Factories Low-process Unit (HAFR Al Batin) | O8: Contractor: Consultant: | U8: SOROH AL KHAIR CONTRACTING CO. EGIS
B10: 4 | D10: Excellent | G10: Quality Management System is being practiced and applies to MODON System | Z10: 90 - 100 | AB10: QC Overall Score | AC10: =Q49 -> 0.79137931 | AN10: =SUM(Z10:Z13) -> 0 | AO10: 100 | AP10: 0.22883295
B11: 3 | D11: Good | G11: Evidence of compliance with plans and procedures. | Z11: 80 - 89 | AN11: =SUM(Y10:Y14) -> 0 | AO11: 89 | AP11: 0.20366133
